file_name: article_7, chunk_size: 1024, output_len: 25
Time: 11.7458
file_name: article_7, chunk_size: 1024, output_len: 50
Time: 14.7764
file_name: article_7, chunk_size: 1024, output_len: 75
Time: 18.0661
file_name: article_7, chunk_size: 1024, output_len: 100
Error happens when executing Parrot program:  <class 'requests.exceptions.ConnectionError'> ConnectionError(ProtocolError('Connection aborted.', RemoteDisconnected('Remote end closed connection without response')))
Traceback:  Traceback (most recent call last):
  File "/home/v-chaofanlin/miniconda3/envs/parrot/lib/python3.10/site-packages/urllib3/connectionpool.py", line 793, in urlopen
    response = self._make_request(
  File "/home/v-chaofanlin/miniconda3/envs/parrot/lib/python3.10/site-packages/urllib3/connectionpool.py", line 537, in _make_request
    response = conn.getresponse()
  File "/home/v-chaofanlin/miniconda3/envs/parrot/lib/python3.10/site-packages/urllib3/connection.py", line 466, in getresponse
    httplib_response = super().getresponse()
  File "/home/v-chaofanlin/miniconda3/envs/parrot/lib/python3.10/http/client.py", line 1375, in getresponse
    response.begin()
  File "/home/v-chaofanlin/miniconda3/envs/parrot/lib/python3.10/http/client.py", line 318, in begin
    version, status, reason = self._read_status()
  File "/home/v-chaofanlin/miniconda3/envs/parrot/lib/python3.10/http/client.py", line 287, in _read_status
    raise RemoteDisconnected("Remote end closed connection without"
http.client.RemoteDisconnected: Remote end closed connection without response

During handling of the above exception, another exception occurred:

Traceback (most recent call last):
  File "/home/v-chaofanlin/miniconda3/envs/parrot/lib/python3.10/site-packages/requests/adapters.py", line 486, in send
    resp = conn.urlopen(
  File "/home/v-chaofanlin/miniconda3/envs/parrot/lib/python3.10/site-packages/urllib3/connectionpool.py", line 847, in urlopen
    retries = retries.increment(
  File "/home/v-chaofanlin/miniconda3/envs/parrot/lib/python3.10/site-packages/urllib3/util/retry.py", line 470, in increment
    raise reraise(type(error), error, _stacktrace)
  File "/home/v-chaofanlin/miniconda3/envs/parrot/lib/python3.10/site-packages/urllib3/util/util.py", line 38, in reraise
    raise value.with_traceback(tb)
  File "/home/v-chaofanlin/miniconda3/envs/parrot/lib/python3.10/site-packages/urllib3/connectionpool.py", line 793, in urlopen
    response = self._make_request(
  File "/home/v-chaofanlin/miniconda3/envs/parrot/lib/python3.10/site-packages/urllib3/connectionpool.py", line 537, in _make_request
    response = conn.getresponse()
  File "/home/v-chaofanlin/miniconda3/envs/parrot/lib/python3.10/site-packages/urllib3/connection.py", line 466, in getresponse
    httplib_response = super().getresponse()
  File "/home/v-chaofanlin/miniconda3/envs/parrot/lib/python3.10/http/client.py", line 1375, in getresponse
    response.begin()
  File "/home/v-chaofanlin/miniconda3/envs/parrot/lib/python3.10/http/client.py", line 318, in begin
    version, status, reason = self._read_status()
  File "/home/v-chaofanlin/miniconda3/envs/parrot/lib/python3.10/http/client.py", line 287, in _read_status
    raise RemoteDisconnected("Remote end closed connection without"
urllib3.exceptions.ProtocolError: ('Connection aborted.', RemoteDisconnected('Remote end closed connection without response'))

During handling of the above exception, another exception occurred:

Traceback (most recent call last):
  File "/home/v-chaofanlin/ParrotServe/parrot/frontend/pfunc/vm.py", line 353, in running_scope
    yield
  File "/home/v-chaofanlin/ParrotServe/parrot/frontend/pfunc/vm.py", line 402, in run
    loop.run_until_complete(coroutine)
  File "/home/v-chaofanlin/miniconda3/envs/parrot/lib/python3.10/asyncio/base_events.py", line 649, in run_until_complete
    return future.result()
  File "/home/v-chaofanlin/ParrotServe/artifact/figure13/bench_arxiv_parrot.py", line 114, in _main
    output.get(P.PerformanceCriteria.LATENCY)
  File "/home/v-chaofanlin/ParrotServe/parrot/frontend/pfunc/semantic_variable.py", line 127, in get
    self.content = self._get_semantic_variable(criteria)
  File "/home/v-chaofanlin/ParrotServe/parrot/frontend/pfunc/semantic_variable.py", line 75, in _get_semantic_variable
    return self._virtual_machine_env.get_semantic_variable_handler(
  File "/home/v-chaofanlin/ParrotServe/parrot/frontend/pfunc/vm.py", line 136, in get_semantic_variable_handler
    resp = get_semantic_variable(
  File "/home/v-chaofanlin/ParrotServe/parrot/protocol/public/apis.py", line 221, in get_semantic_variable
    raise e
  File "/home/v-chaofanlin/ParrotServe/parrot/protocol/public/apis.py", line 207, in get_semantic_variable
    return send_http_request(
  File "/home/v-chaofanlin/ParrotServe/parrot/protocol/http_utils.py", line 55, in send_http_request
    raise error
  File "/home/v-chaofanlin/ParrotServe/parrot/protocol/http_utils.py", line 32, in send_http_request
    resp = requests.get(url, json=kwargs, timeout=timeout)
  File "/home/v-chaofanlin/miniconda3/envs/parrot/lib/python3.10/site-packages/requests/api.py", line 73, in get
    return request("get", url, params=params, **kwargs)
  File "/home/v-chaofanlin/miniconda3/envs/parrot/lib/python3.10/site-packages/requests/api.py", line 59, in request
    return session.request(method=method, url=url, **kwargs)
  File "/home/v-chaofanlin/miniconda3/envs/parrot/lib/python3.10/site-packages/requests/sessions.py", line 589, in request
    resp = self.send(prep, **send_kwargs)
  File "/home/v-chaofanlin/miniconda3/envs/parrot/lib/python3.10/site-packages/requests/sessions.py", line 703, in send
    r = adapter.send(request, **kwargs)
  File "/home/v-chaofanlin/miniconda3/envs/parrot/lib/python3.10/site-packages/requests/adapters.py", line 501, in send
    raise ConnectionError(err, request=request)
requests.exceptions.ConnectionError: ('Connection aborted.', RemoteDisconnected('Remote end closed connection without response'))

